Workbook

Sheet Hướng dẫn
A1: HW03 – Task 1B · Sổ thực thi Checklist GUI trên EMS
A2: Phạm Anh Hào – 23127362 · Kịch bản A – Admin tạo và quản lý sự kiện
A4: Ba màn hình phụ trách
A5: A1 — Danh sách Events (bộ lọc trạng thái, chấm thông báo)
A6: A2 — Form Add/Edit Event (upload 4:3 + 24:9, rich-text, 6 trường ngày giờ ràng buộc chéo)
A7: A4 — Duyệt Participants & Reviews (màu trạng thái, progress bar, Export Excel)
A9: Cách điền
A10: Chỉ điền vào các ô TÔ VÀNG ở sheet "Checklist_Run". Các cột trắng là dữ liệu gốc, không sửa.
A11: Cột kết quả (A1 / A2 / A4) có dropdown, chỉ chọn một trong ba giá trị:
A12: P = Passed → không cần ghi chú, không cần ảnh
A13: F = Failed → BẮT BUỘC ghi lý do vào cột Ghi chú + chụp ảnh + ghi tên file ảnh
A14: N/A = Không áp dụng → BẮT BUỘC ghi lý do vào cột Ghi chú. KHÔNG được để trống dòng.
... A34: Checklist_Run và Bug_Log phải do bạn tự thao tác trên EMS thật và tự chụp ảnh.

Sheet Checklist_Run
A1: ID | B1: IA | C1: Mục kiểm tra | D1: Cách kiểm chứng | E1: Nguồn | F1: Ưu tiên | G1: A1 | H1: Ghi chú A1 | I1: A2 | J1: Ghi chú A2 | K1: A4 | L1: Ghi chú A4
A2: GUI-01-01 | B2: IA-01 | C2: Layout, canh lề, typography và bảng màu nhất quán giữa các màn hình cùng loại (list, form, chi tiết) | D2: Mở lần lượt vài màn hình cùng loại ở cả bốn nhóm A–D, so vị trí tiêu đề, khoảng cách, cỡ/kiểu chữ và màu | E2: Norman – Consistency; Nielsen #4 | F2: Cao | G2: P | I2: P | K2: P
A3: GUI-01-02 | B3: IA-01 | C3: Thuật ngữ, nhãn và thông báo dùng ngôn ngữ quen thuộc với người tổ chức/người tham dự sự kiện; không hiển thị tên trường cơ sở dữ liệu, mã trạng thái nội bộ hoặc thuật ngữ kỹ thuật khi không có giải thích | D3: Rà tiêu đề, nhãn nút, badge, thông báo và dialog trên các màn hình; đặc biệt kiểm tra lỗi API, vai trò và trạng thái sự kiện/yêu cầu hỗ trợ | E3: Nielsen #2 – Match between system and the real world; Norman – Mapping | F3: Cao | G3: P | I3: P | K3: P
A4: GUI-01-03 | B4: IA-01 | C4: Mỗi màn hình có thứ bậc thị giác rõ: tiêu đề, nội dung chính và hành động chính nổi bật; hành động phụ/phá huỷ không cạnh tranh với hành động chính; thông tin không liên quan hoặc lặp lại được lược bỏ | D4: Quan sát màn hình ở kích thước desktop và mobile; xác định trong 5 giây mục đích trang và hành động chính, rồi kiểm tra các nội dung/nút trùng lặp hoặc gây nhiễu | E4: Nielsen #8 – Aesthetic and minimalist design; Shneiderman #8 – Reduce short-term memory load | F4: Cao | G4: P | I4: P | K4: P
A5: GUI-01-04 | B5: IA-01 | C5: Thành phần tương tác thể hiện đúng khả năng sử dụng: nút, liên kết, vùng kéo-thả và hàng có thể mở chi tiết nhìn ra là có thể thao tác; nội dung tĩnh không tạo cảm giác có thể bấm; trạng thái disabled khác biệt rõ với trạng thái bình thường | D5: Quan sát mà chưa bấm để dự đoán thành phần nào tương tác được, sau đó dùng chuột/bàn phím kiểm chứng; kiểm tra các nút disabled, vùng upload và hàng trong bảng | E5: Norman – Affordance, Visibility; Nielsen #6 – Recognition rather than recall | F5: Cao | G5: P | I5: P | K5: P
A6: GUI-01-05 | B6: IA-01 | C6: Icon dùng cùng một ý nghĩa và cùng một hình dạng ở mọi nơi xuất hiện (icon xoá, sửa, export, thông báo… không đổi hình giữa các màn hình) | D6: Liệt kê các icon lặp lại trên Events, Users, Support Requests, Dashboard; đối chiếu hình dạng và hành động gắn với từng icon | E6: Nielsen #4; Norman – Signifiers | F6: Trung bình | G6: P | I6: P | K6: P
A7: GUI-01-06 | B7: IA-01 | C7: Cùng một dữ liệu nghiệp vụ được trình bày nhất quán về tên gọi, đơn vị, thứ tự, biểu tượng **và** định dạng ngày/giờ/số (dấu phân cách nghìn/thập phân, 12h/24h) giữa danh sách, trang chi tiết, form và file export | D7: Chọn một Event/User/Support Request, đối chiếu cùng dữ liệu ở danh sách, chi tiết, form chỉnh sửa và file export; đặc biệt so sánh cùng một mốc thời gian hoặc con số (VD: thời gian sự kiện, số người đăng ký) hiển thị ở list, detail, vé QR và file Excel; ghi nhận mọi chỗ đổi tên, đổi đơn vị hoặc mâu thuẫn giá trị/định dạng | E7: Nielsen #4 – Consistency and standards; Norman – Consistency, Mapping | F7: Cao | G7: P | I7: P | K7: P
A8: GUI-01-07 | B8: IA-01 | C8: Khi đổi EN ↔ VI, toàn bộ nhãn, thông báo lỗi và trạng thái đều được dịch, không tràn/vỡ layout, thuộc tính `lang` đổi theo, và ngày giờ/số được định dạng theo locale đang chọn một cách nhất quán trên mọi màn hình | D8: Chuyển ngôn ngữ trên nhiều màn hình, rà chuỗi còn sót, kiểm tra tràn chữ và `lang`; đối chiếu cùng một mốc thời gian sự kiện hiển thị ở danh sách, trang chi tiết, vé và audit log ở cả hai ngôn ngữ | E8: Nielsen #2; WCAG 3.1.2 | F8: Cao | G8: P | I8: P | K8: P
A9: GUI-01-08 | B9: IA-01 | C9: Trạng thái rỗng và trạng thái đang tải hiển thị thông báo/placeholder có ý nghĩa (kèm gợi ý hành động), không để vùng trắng trơn | D9: Lọc/tìm ra tập rỗng hoặc mở màn hình sau khi dữ liệu reset; tải chậm để quan sát loading | E9: Nielsen #1 | F9: Trung bình | G9: P | I9: P | K9: P
A10: GUI-01-09 | B10: IA-01 | C10: Mật độ thông tin và khoảng trắng hợp lý trên các màn hình nhiều dữ liệu (KPI Dashboard, bảng danh sách, panel cấu hình) — không chồng chữ, không chật đến mức khó phân biệt hàng/cột | D10: Mở Dashboard và các bảng danh sách ở độ phân giải desktop chuẩn, kiểm tra khoảng cách dòng, cột, thẻ KPI có bị dính vào nhau không | E10: Nielsen #8 (Aesthetic and minimalist design) | F10: Trung bình | G10: P | I10: P | K10: P
A11: GUI-01-10 | B11: IA-01 | C11: Ở bề rộng màn hình hẹp (≈320–480 px), nội dung tự sắp xếp lại mà không phải cuộn ngang, bảng danh sách vẫn đọc được đủ thông tin, dialog nằm gọn trong khung nhìn và đóng được, mọi vùng chạm đạt kích thước tối thiểu | D11: Thu cửa sổ về 320 px hoặc dùng chế độ thiết bị di động trên các danh sách Events/Users/Support, form Add/Edit Event và một dialog xác nhận; kiểm tra cuộn ngang, cách bảng thu gọn, nút đóng dialog và kích thước vùng chạm | E11: WCAG 1.4.10; WCAG 2.5.5 | F11: Cao | G11: F | H11: Table từ đầu đã quá dài nên các cột càng về sau phải cuộn ngang mới thấy được dù mang hình có kích thước lớn thế nào | I11: P | K11: N/A | L11: Các cột trong table cột không thu gọn nên phải cuộn ngang
A12: GUI-01-11 | B12: IA-01 | C12: Văn bản và thành phần giao diện đạt tỷ lệ tương phản tối thiểu so với nền, thứ tự heading đi liền mạch không nhảy cấp, và mọi nút chỉ có icon đều có tên trợ năng mô tả hành động | D12: Dùng công cụ đo tương phản trên nhãn, badge, chữ trên nền màu; rà cây heading của vài trang bằng trình kiểm tra phần tử; kiểm tra từng nút icon (xoá, sửa, đóng lightbox, chuyển ngôn ngữ) xem có nhãn văn bản | E12: WCAG 1.4.3; WCAG 1.3.1; WCAG 4.1.2 | F12: Cao | G12: F | H12: Fail 2/3 vế. (1) Tương phản: Lighthouse Accessibility báo 'Background and foreground colors do not have a sufficient contrast ratio'. (3) Nút icon: 2 nút phân trang ‹ và › không có aria-label, trình đọc màn hình đọc là 'button'. (2) Thứ tự heading: đạt, không bị báo lỗi. Điểm Lighthouse Accessibility: 88. | I12: F | J12: Fail 2/3 vế. (1) Tương phản: Lighthouse báo lỗi contrast. (3) Nút icon: Lighthouse báo 'Buttons do not have an accessible name'. (2) Thứ tự heading: đạt. Điểm Lighthouse Accessibility: 77 — thấp nhất trong 3 màn hình do form nhiều điều khiển. | K12: F | L12: Fail 2/3 vế. (1) Tương phản: Lighthouse báo lỗi contrast. (2) Thứ tự heading: Lighthouse báo 'Heading elements are not in a sequentially-descending order' — đây là màn hình DUY NHẤT fail vế heading. (3) Nút icon: đạt, không bị báo. Điểm Lighthouse: 87.
A13: GUI-01-12 | B13: IA-01 | C13: Tiêu đề tab trình duyệt, favicon và logo hiển thị đúng, nhất quán trên mọi màn hình, tiêu đề tab phản ánh đúng ngữ cảnh đang xem | D13: Chuyển qua các màn hình khác nhau (Dashboard, Event detail, Support detail…), quan sát tiêu đề tab trình duyệt có đổi theo nội dung không | E13: Nielsen #1; Shneiderman #1 | F13: Thấp | G13: P | I13: P | K13: P
A14: GUI-02-01 | B14: IA-02 | C14: Mọi trường bắt buộc được đánh dấu nhất quán bằng một quy ước duy nhất, và quy ước đó được giải thích | D14: Rà toàn bộ trường trên nhiều form (Add/Edit Event, đăng ký, support), đối chiếu ký hiệu trường bắt buộc | E14: Nielsen #4 | F14: Cao | G14: P | I14: P | K14: P
A15: GUI-02-02 | B15: IA-02 | C15: Mọi input có nhãn nhìn thấy được và liên kết chương trình với trường (`<label for>` ↔ `id` duy nhất) | D15: Dùng trình kiểm tra phần tử/đọc màn hình trên vài form, xác nhận từng input có label gắn đúng và id không trùng | E15: WCAG 1.3.1; Nielsen #6 | F15: Cao | G15: P | I15: F | J15: Lighthouse báo 'Form elements do not have associated labels'. Ngoài ra khảo sát DOM cho thấy 6 ô ngày giờ (Start, End, Check-in Open/Close, Registration Open/Close) dùng CHUNG một id 'datetime-iso-input' — vi phạm trực tiếp yêu cầu id duy nhất; và cả 6 dùng chung aria-label 'Select date and time' nên không phân biệt được bằng trình đọc màn hình. | K15: P
A16: GUI-02-03 | B16: IA-02 | C16: Lỗi validation hiện ngay cạnh trường sai, mô tả cụ thể và gợi ý cách sửa (không chỉ báo lỗi chung ở đầu form) | D16: Bỏ trống/nhập sai từng trường (gồm ràng buộc ngày giờ chéo), quan sát vị trí và nội dung thông báo lỗi | E16: Nielsen #9; Norman – Feedback | F16: Cao | G16: N/A | H16: Màn hình này không có nhập liệu | I16: P | K16: N/A | L16: Màn hình này không có nhập liệu
A17: GUI-02-04 | B17: IA-02 | C17: Upload ảnh/file kiểm soát và truyền đạt ràng buộc (tỷ lệ 4:3 & 24:9, định dạng, dung lượng); từ chối file sai kèm thông báo rõ | D17: Thử upload ảnh sai tỷ lệ, sai định dạng, quá dung lượng ở form Event và support; đọc thông báo trả về | E17: Nielsen #5; Norman – Constraints | F17: Cao | G17: N/A | H17: Màn hình này không có input ảnh | I17: P | K17: N/A | L17: Màn hình này không có input ảnh
A18: GUI-02-05 | B18: IA-02 | C18: Mọi điều khiển chọn giá trị (dropdown đơn/đa chọn, checkbox, radio, toggle, date-time picker, number input, textarea, rich-text editor, thang sao 1–5) thể hiện rõ giá trị đang chọn, thao tác được bằng bàn phím, và nạp lại đúng giá trị đã lưu khi mở lại ở chế độ Edit | D18: Trên form Add/Edit Event, cấu hình đăng ký, form đăng ký và form đánh giá: đặt giá trị cho từng loại điều khiển bằng chuột rồi bằng bàn phím, lưu, mở lại bản ghi và đối chiếu giá trị hiển thị | E18: Norman – Visibility; WCAG 2.1.1; Nielsen #6 | F18: Cao | G18: P | I18: P | K18: P
A19: GUI-02-06 | B19: IA-02 | C19: Định dạng, giới hạn và ví dụ nhập liệu cần thiết được hiển thị **trước khi** người dùng nhập; placeholder chỉ là ví dụ, không thay thế nhãn hoặc hướng dẫn quan trọng | D19: Kiểm tra các trường ngày giờ, Max Slots, Member Code, email, nội dung Rich-Text và attachment; đặt con trỏ/nhập thử để xem hướng dẫn có biến mất khiến người dùng phải nhớ hay không | E19: Nielsen #5 – Error prevention; Nielsen #6 – Recognition rather than recall; Norman – Visibility, Constraints | F19: Cao | G19: N/A | H19: Màn hình này không có nhập liệu | I19: P | K19: N/A | L19: Màn hình này không có nhập liệu
A20: GUI-02-07 | B20: IA-02 | C20: Giá trị mặc định giúp giảm thao tác nhưng phải an toàn và phù hợp ngữ cảnh; hệ thống không tự chọn thay người dùng đối với vai trò, đồng ý/consent, publish, block, delete hoặc lựa chọn có hậu quả lớn | D20: Mở form ở trạng thái tạo mới và chỉnh sửa; rà tất cả giá trị được điền/chọn sẵn, thử lưu mà không thay đổi rồi đánh giá hậu quả | E20: Nielsen #5 – Error prevention; Shneiderman #5 – Prevent errors; Norman – Constraints | F20: Cao | G20: N/A | H20: Màn hình này không có nhập liệu | I20: P | K20: N/A | L20: Màn hình này không có nhập liệu
A21: GUI-02-08 | B21: IA-02 | C21: Các trường phụ thuộc nhau phản ánh ràng buộc ngay khi giá trị liên quan thay đổi: lựa chọn không hợp lệ bị ngăn hoặc vô hiệu hoá và có giải thích ngắn, thay vì chờ đến lúc Submit mới báo lỗi | D21: Thay đổi cặp ngày bắt đầu/kết thúc, thời gian đăng ký/check-in, Max Slots/Waitlist và toggle vai trò; quan sát trường phụ thuộc, giá trị cũ và thông báo giải thích | E21: Nielsen #5 – Error prevention; Norman – Constraints, Mapping, Feedback | F21: Cao | G21: N/A | H21: Màn hình này không có nhập liệu | I21: P | K21: N/A | L21: Màn hình này không có nhập liệu
A22: GUI-02-09 | B22: IA-02 | C22: Khi **chủ động** rời form còn thay đổi chưa lưu bằng Back, Cancel, menu, refresh hoặc đóng tab, hệ thống cảnh báo rõ và cho phép tiếp tục chỉnh sửa; chọn ở lại không được làm mất dữ liệu đã nhập | D22: Sửa ít nhất hai trường nhưng chưa lưu, lần lượt thử Back, Cancel, đổi menu và refresh; kiểm tra dialog, nút "ở lại/rời đi" và nội dung form sau khi chọn ở lại | E22: Nielsen #3 – User control and freedom; Shneiderman #6 – Permit easy reversal of actions | F22: Cao | G22: N/A | H22: Màn hình này không có nhập liệu | I22: N/A | J22: Không có nủt back nên không thể kiểm chứng | K22: N/A | L22: Màn hình này không có nhập liệu
A23: GUI-02-10 | B23: IA-02 | C23: Toolbar rich-text editor (bold, italic, list, chèn ảnh/link) phản ánh đúng trạng thái vùng văn bản đang chọn, và nội dung định dạng được giữ nguyên sau khi lưu và tải lại | D23: Bôi đen từng đoạn văn bản khác nhau trong mô tả sự kiện, áp định dạng, lưu, mở lại bản ghi và đối chiếu định dạng có còn đúng không | E23: Norman – Feedback; Nielsen #1 | F23: Cao | G23: N/A | H23: Màn hình này không có nhập liệu | I23: P | K23: N/A | L23: Màn hình này không có nhập liệu
A24: GUI-02-11 | B24: IA-02 | C24: Trường optional, trường disabled (do chưa đủ điều kiện) và trường readonly được phân biệt rõ bằng thị giác lẫn markup (`aria-disabled`, `readonly`), không chỉ đơn thuần "không bấm được" | D24: Rà các form có trường điều kiện (VD: vai trò phụ chỉ bật khi chọn role tương ứng), kiểm tra bằng DOM/inspector và bằng mắt xem có phân biệt được optional/disabled/readonly | E24: Nielsen #4; WCAG 4.1.2 | F24: Trung bình | G24: N/A | H24: Màn hình này không có nhập liệu | I24: F | J24: Có một số trường bắt buộc fill nhưng lại không có dấu hiệu lưu ý mà phải submit thất bại mới biết | K24: N/A | L24: Màn hình này không có nhập liệu
A25: GUI-02-12 | B25: IA-02 | C25: Form dài (nhiều section: thumbnail, banner, rich-text, ngày giờ, registration…) được chia thành các phần có tiêu đề rõ ràng, giúp người dùng định vị đang ở phần nào khi cuộn | D25: Mở form Add/Edit Event, cuộn qua toàn bộ chiều dài form, kiểm tra mỗi section có heading/label phân tách rõ, không bị trộn lẫn giữa các nhóm trường khác nhau | E25: Nielsen #6 – Recognition rather than recall; Norman – Mapping | F25: Trung bình | G25: N/A | H25: Màn hình này không có nhập liệu | I25: P | K25: N/A | L25: Màn hình này không có nhập liệu
A26: GUI-02-13 | B26: IA-02 | C26: Dữ liệu đang nhập dở không bị mất khi **bị động** gặp sự cố: tải lại trang do lỗi mạng tạm thời hoặc chuyển tab rồi quay lại (autosave/draft hoặc khôi phục được nội dung) | D26: Nhập dở form Add/Edit Event hoặc form support request, chuyển tab/reload trong thời gian ngắn, quay lại kiểm tra dữ liệu còn hay mất | E26: Nielsen #5; Norman – User control | F26: Trung bình | G26: N/A | H26: Màn hình này không có nhập liệu | I26: P | K26: N/A | L26: Màn hình này không có nhập liệu
A27: GUI-03-01 | B27: IA-03 | C27: Breadcrumb/nút back/return đưa về đúng màn hình cha, và deep link tới chi tiết mở đúng đối tượng | D27: Đi sâu vào chi tiết (event, user, request) rồi back; mở trực tiếp một deep link và đối chiếu đối tượng | E27: Nielsen #3; Shneiderman #3 | F27: Trung bình | G27: N/A | H27: Màn hình này không có nút back | I27: N/A | J27: Màn hình này không có nút back | K27: N/A | L27: Màn hình này không có nút back
A28: GUI-03-02 | B28: IA-03 | C28: Điều hướng bàn phím hoạt động: thứ tự tab hợp lý theo dòng đọc, viền focus nhìn thấy được, Esc đóng dialog, focus không thoát khỏi dialog đang mở | D28: Chỉ dùng Tab/Shift-Tab/Esc duyệt form và dialog, quan sát vòng focus và viền focus | E28: WCAG 2.4.7; WCAG 2.1.2; Shneiderman #3 | F28: Cao | G28: P | I28: P | K28: P
A29: GUI-03-03 | B29: IA-03 | C29: Cấu trúc điều hướng (sidebar/menu/tab) đồng nhất và giữ nguyên vị trí khi chuyển giữa các khu vực, phản ánh đúng phân quyền đang đăng nhập | D29: Đăng nhập bằng các vai trò khác nhau, chuyển khu vực, kiểm tra menu ổn định và chỉ hiện mục được phép | E29: Nielsen #4; Norman – Mapping | F29: Trung bình | G29: P | I29: P | K29: P
A30: GUI-03-04 | B30: IA-03 | C30: Vị trí đang đứng được hiển thị rõ: mục menu/tab tương ứng được đánh dấu active và tiêu đề trang khớp nhãn menu | D30: Duyệt từng mục menu/tab, kiểm tra highlight active và đối chiếu tiêu đề trang với nhãn | E30: Nielsen #1; Shneiderman #1 | F30: Cao | G30: P | I30: P | K30: P
A31: GUI-03-05 | B31: IA-03 | C31: Mọi danh sách/bảng hiển thị rõ tiêu chí tìm kiếm và bộ lọc đang áp dụng cùng tổng số kết quả, phân trang cho biết trang hiện tại trên tổng số trang, và bộ tiêu chí này được giữ nguyên khi quay lại từ màn hình chi tiết | D31: Trên các danh sách Events / Users / Support Requests: nhập từ khoá, chọn bộ lọc, sang trang 2, mở một bản ghi rồi bấm back → kiểm tra chip/nhãn tiêu chí, số kết quả, chỉ báo trang và trạng thái sau khi quay lại | E31: Nielsen #1; Shneiderman #3 | F31: Cao | G31: P | I31: N/A | J31: Màn hình này không có bộ lọc | K31: P
A32: GUI-03-06 | B32: IA-03 | C32: Các chức năng được nhóm và đặt tên theo mục tiêu của người dùng, không theo cấu trúc kỹ thuật của hệ thống; những chức năng liên quan nằm gần nhau và các nhóm khác nhau được phân tách rõ | D32: Nhờ người chưa quen EMS chỉ vị trí để tạo sự kiện, đăng ký, lấy QR, quản lý user hoặc xử lý support mà không hướng dẫn; ghi nhận mục bị tìm sai hoặc nhãn gây hiểu nhầm | E32: Nielsen #2 – Match between system and the real world; Nielsen #6 – Recognition rather than recall; Norman – Mapping | F32: Cao | G32: P | I32: P | K32: P
A33: GUI-03-07 | B33: IA-03 | C33: Tác vụ thường xuyên có đường đi hiệu quả cho người dùng thành thạo (VD: hành động trực tiếp trên từng hàng, thao tác hàng loạt hoặc phím tắt khi phù hợp) nhưng không làm rối luồng cơ bản của người mới | D33: So bước để thực hiện cùng một tác vụ lặp lại trên nhiều bản ghi; kiểm tra hành động nhanh có dễ tìm, có nhãn rõ và không buộc người mới phải học phím tắt hay không | E33: Nielsen #7 – Flexibility and efficiency of use; Shneiderman #2 – Enable frequent users to use shortcuts | F33: Trung bình | G33: P | I33: P | K33: P
A34: GUI-03-08 | B34: IA-03 | C34: Màn hình từ chối truy cập (do không đủ quyền) hoặc báo tài nguyên không còn khả dụng (đã xoá/hết hạn chia sẻ/deep link vượt quyền) không trở thành "ngõ cụt": hệ thống giải thích ngắn gọn tình trạng và cung cấp đường điều hướng hợp lệ về khu vực người dùng có quyền truy cập, không buộc họ chỉ dựa vào nút Back của trình duyệt | D34: Đăng nhập bằng tài khoản không phải admin, dán trực tiếp URL của một trang quản trị (VD: danh sách Users) vào thanh địa chỉ; đồng thời truy cập deep link tới bản ghi đã xoá/không còn chia sẻ và dùng liên kết đã hết hiệu lực; kiểm tra thông báo cùng CTA về danh sách, dashboard hoặc khu vực an toàn phù hợp | E34: Nielsen #3 – User control and freedom; Nielsen #9 – Help users recognize, diagnose, and recover from errors; Norman – Mapping | F34: Cao | G34: P | I34: P | K34: P
A35: GUI-03-09 | B35: IA-03 | C35: Điều khiển tuân theo quy ước Web: liên kết dùng để chuyển trang, nút dùng để thực hiện hành động; đích mở tab/cửa sổ mới được báo trước; Back không tự gửi lại form hay lặp lại hành động đã hoàn tất | D35: Duyệt các liên kết, nút icon, Preview, Export và liên kết ngoài; mở đích rồi dùng Back/Forward để kiểm tra có điều hướng bất ngờ, submit lại hoặc tạo bản ghi trùng không | E35: Nielsen #4 – Consistency and standards; Norman – Affordance, Consistency | F35: Cao | G35: P | I35: P | K35: F | L35: Lighthouse báo 2 lỗi vi phạm quy ước điều khiển Web: 'Links do not have a discernible name' (link không có tên đọc được) và '[aria-*] attributes do not match their roles' (dùng thẻ span kèm aria-haspopup/aria-expanded thay vì button có role hợp lệ).
A36: GUI-03-10 | B36: IA-03 | C36: Kéo-thả sắp xếp lại (VD: thứ tự vai trò phụ trong cấu hình đăng ký) có phản hồi thị giác rõ trong lúc kéo, và thứ tự mới được giữ nguyên sau khi lưu/tải lại | D36: Kéo-thả để đổi thứ tự trong panel cấu hình vai trò phụ, quan sát chỉ báo vị trí thả trong lúc kéo, lưu rồi tải lại trang để đối chiếu thứ tự | E36: Norman – Feedback/Visibility; WCAG 2.5.1 | F36: Trung bình | G36: N/A | H36: Màn hình này không có nhập liệu | I36: F | J36: Màn hình này không có khả năng kéo thả file | K36: N/A | L36: Màn hình này không có nhập liệu
A37: GUI-03-11 | B37: IA-03 | C37: Ô tìm kiếm, bộ lọc và nút sắp xếp trên các danh sách thao tác được hoàn toàn bằng bàn phím và có nhãn cho trình đọc màn hình, không chỉ dùng được bằng chuột | D37: Dùng Tab/Enter/phím mũi tên để nhập từ khoá tìm kiếm, mở dropdown lọc, chọn tiêu chí sắp xếp trên danh sách Events/Users/Support mà không chạm chuột | E37: WCAG 2.1.1; WCAG 4.1.2 | F37: Cao | G37: P | I37: N/A | J37: Màn hình này không có table | K37: P
A38: GUI-03-12 | B38: IA-03 | C38: Trạng thái đóng/mở của sidebar (nếu có thể thu gọn) được giữ nguyên khi điều hướng giữa các trang trong cùng phiên làm việc | D38: Thu gọn sidebar, chuyển qua vài trang khác nhau trong cùng phiên đăng nhập, kiểm tra sidebar có tự bung lại không | E38: Nielsen #4; Norman – Mapping | F38: Thấp | G38: P | I38: P | K38: P
A39: GUI-04-01 | B39: IA-04 | C39: Mọi hành động phá huỷ/khó hồi phục (xoá, chặn, reset, huỷ đăng ký) đều có dialog xác nhận nêu rõ đối tượng bị tác động | D39: Bấm xoá/chặn/reset/huỷ, đọc dialog xem có nêu tên đối tượng cụ thể và cho phép huỷ thao tác | E39: Shneiderman #6; Nielsen #3 | F39: Cao | G39: P | I39: P | K39: N/A | L39: Màn hình này không có chức năng xóa/hủy
A40: GUI-04-02 | B40: IA-04 | C40: Mọi hành động của người dùng đều có phản hồi tức thời (toast/loading/đổi trạng thái) xác nhận thành công hoặc thất bại | D40: Thực hiện lưu/publish/đăng ký/gửi request và các thao tác dài (Export Excel, Preview), quan sát có phản hồi trong thời gian hợp lý | E40: Nielsen #1; Norman – Feedback; Shneiderman #3 | F40: Cao | G40: F | H40: Thao tác xóa không hiển thông báo hay phản hồi nào về việc thực hiện thành công việc xóa event | I40: F | J40: Thao tác lưu nháp không hiển thông báo hay phản hồi nào về việc thực hiện thành công | K40: F | L40: Có một số thao tác không hiển thông báo hay phản hồi nào
...

Sheet Thống kê
A1: Thống kê tự động — số liệu điền vào README
A2: Mọi ô đều là công thức, tự cập nhật khi bạn điền Checklist_Run.
A4: Màn hình | B4: Passed | C4: Failed | D4: N/A | E4: Chưa điền | F4: Tổng mục
A5: A1 — Danh sách Events | B5: =COUNTIF(Checklist_Run!G2:G49,"P") -> 29 | C5: =COUNTIF(Checklist_Run!G2:G49,"F") -> 5 | D5: =COUNTIF(Checklist_Run!G2:G49,"N/A") -> 14 | E5: =COUNTBLANK(Checklist_Run!G2:G49) -> 0 | F5: =SUM(B5:E5) -> 48
A6: A2 — Form Add/Edit Event | B6: =COUNTIF(Checklist_Run!I2:I49,"P") -> 35 | C6: =COUNTIF(Checklist_Run!I2:I49,"F") -> 7 | D6: =COUNTIF(Checklist_Run!I2:I49,"N/A") -> 6 | E6: =COUNTBLANK(Checklist_Run!I2:I49) -> 0 | F6: =SUM(B6:E6) -> 48
A7: A4 — Participants & Reviews | B7: =COUNTIF(Checklist_Run!K2:K49,"P") -> 28 | C7: =COUNTIF(Checklist_Run!K2:K49,"F") -> 5 | D7: =COUNTIF(Checklist_Run!K2:K49,"N/A") -> 15 | E7: =COUNTBLANK(Checklist_Run!K2:K49) -> 0 | F7: =SUM(B7:E7) -> 48
A8: TỔNG (144 ô) | B8: =SUM(B5:B7) -> 92 | C8: =SUM(C5:C7) -> 17 | D8: =SUM(D5:D7) -> 35 | E8: =SUM(E5:E7) -> 0 | F8: =SUM(F5:F7) -> 144
A10: Số mục Failed theo từng IA (gộp cả ba màn hình)
A11: IA | B11: A1 | C11: A2 | D11: A4 | E11: Tổng Failed
A12: IA-01 | B12: =COUNTIFS(Checklist_Run!$B$2:$B$49,$A12,Checklist_Run!G2:G49,"F") -> 2 | C12: =COUNTIFS(Checklist_Run!$B$2:$B$49,$A12,Checklist_Run!I2:I49,"F") -> 1 | D12: =COUNTIFS(Checklist_Run!$B$2:$B$49,$A12,Checklist_Run!K2:K49,"F") -> 1 | E12: =SUM(B12:D12) -> 4
A13: IA-02 | B13: =COUNTIFS(Checklist_Run!$B$2:$B$49,$A13,Checklist_Run!G2:G49,"F") -> 0 | C13: =COUNTIFS(Checklist_Run!$B$2:$B$49,$A13,Checklist_Run!I2:I49,"F") -> 2 | D13: =COUNTIFS(Checklist_Run!$B$2:$B$49,$A13,Checklist_Run!K2:K49,"F") -> 0 | E13: =SUM(B13:D13) -> 2
A14: IA-03 | B14: =COUNTIFS(Checklist_Run!$B$2:$B$49,$A14,Checklist_Run!G2:G49,"F") -> 0 | C14: =COUNTIFS(Checklist_Run!$B$2:$B$49,$A14,Checklist_Run!I2:I49,"F") -> 1 | D14: =COUNTIFS(Checklist_Run!$B$2:$B$49,$A14,Checklist_Run!K2:K49,"F") -> 1 | E14: =SUM(B14:D14) -> 2
A15: IA-04 | B15: =COUNTIFS(Checklist_Run!$B$2:$B$49,$A15,Checklist_Run!G2:G49,"F") -> 3 | C15: =COUNTIFS(Checklist_Run!$B$2:$B$49,$A15,Checklist_Run!I2:I49,"F") -> 3 | D15: =COUNTIFS(Checklist_Run!$B$2:$B$49,$A15,Checklist_Run!K2:K49,"F") -> 3 | E15: =SUM(B15:D15) -> 9
A16: Tổng số ô Failed | E16: =SUM(E12:E15) -> 17

Sheet Bug_Log
A1: ID | B1: Kịch bản / Màn hình | C1: Loại | D1: Mô tả | E1: Bước tái hiện / Heuristic | F1: Mức nghiêm trọng | G1: Đề xuất sửa | H1: Tham chiếu ảnh | I1: Thời điểm gửi form | J1: ID mục checklist
A2: =IF(D2="","","BUG-"&TEXT(ROW()-1,"000")) -> BUG-001 | B2: A1 - Danh sách Events | C2: Bug | D2: Hai nút phân trang trang trước (‹) và trang sau (›) chỉ có icon, không có aria-label hay text. Trình đọc màn hình đọc cả hai là "button", không phân biệt được nút nào tiến, nút nào lùi. | E2: Mở /dashboard/admin/events → F12 → Lighthouse → Accessibility → mục "Buttons do not have an accessible name". Heuristic: WCAG 4.1.2 (Name, Role, Value); Nielsen #6. | F2: 2 - Nhỏ | G2: Thêm aria-label="Trang trước" và aria-label="Trang sau" cho hai nút phân trang. | H2: A1_GUI-01-11_pagination-no-name.png | I2: Chưa gửi | J2: GUI-01-11
A3: =IF(D3="","","BUG-"&TEXT(ROW()-1,"000")) -> BUG-002 | B3: A1 - Danh sách Events | C3: Bug | D3: Nút mở menu tài khoản (avatar TLA, góc trên bên phải) dùng thẻ <span> không có role, nhưng lại gắn aria-haspopup="true" và aria-expanded="false". Các thuộc tính ARIA này không hợp lệ trên role ngầm định của span nên bị vô hiệu hoá. Thuộc tính type="button" trên span cũng không có tác dụng. | E3: Mở /dashboard/admin/events → Lighthouse → Accessibility → mục "[aria-*] attributes do not match their roles" → bung Failing Elements. Heuristic: WCAG 4.1.2; Nielsen #4. | F3: 2 - Nhỏ | G3: Đổi <span> thành <button>, hoặc thêm role="button" kèm aria-label="Menu tài khoản". | H3: A1_ARIA_avatar-span-no-role.png | I3: Chưa gửi | J3: GUI-03-09
A4: =IF(D4="","","BUG-"&TEXT(ROW()-1,"000")) -> BUG-003 | B4: Khác | C4: Usability | D4: Nhiều cặp màu chữ/nền trên toàn hệ thống không đạt tỉ lệ tương phản tối thiểu 4.5:1: badge trạng thái nền nhạt (Giới hạn, Không công khai, Sắp tới, Đã xuất bản), tiêu đề cột bảng, placeholder ô tìm kiếm. Lỗi lặp lại trên CẢ BA màn hình A1, A2 và A4 → là vấn đề ở tầng bảng màu dùng chung, không phải lỗi cục bộ. | E4: Chạy Lighthouse Accessibility lần lượt trên /events, /events/create và trang chi tiết sự kiện → mục "Background and foreground colors do not have a sufficient contrast ratio" xuất hiện ở cả ba. Heuristic: WCAG 1.4.3. | F4: 2 - Nhỏ | G4: Rà lại bảng màu ở tầng design system: tăng độ đậm màu chữ trên nền tint nhạt của badge; đổi màu placeholder và tiêu đề cột sang tông đậm hơn. | H4: A1_GUI-01-11_contrast-lighthouse.png, A2_contrast-lighthouse.png, A4_contrast-lighthouse.png | I4: Chưa gửi | J4: GUI-01-11
A5: =IF(D5="","","BUG-"&TEXT(ROW()-1,"000")) -> BUG-004 | B5: A2 - Form Add/Edit Event | C5: Bug | D5: Các trường nhập trên form Tạo sự kiện không có nhãn liên kết chương trình. Nghiêm trọng nhất: sáu ô ngày giờ (Bắt đầu, Kết thúc, Mở/Đóng check-in, Mở/Đóng đăng ký) dùng CHUNG một id "datetime-iso-input" — id trùng là HTML không hợp lệ và phá liên kết label↔input; đồng thời cả sáu dùng chung aria-label "Select date and time" nên trình đọc màn hình không phân biệt được ô nào là ô nào. | E5: Mở /dashboard/admin/events/create → Lighthouse → "Form elements do not have associated labels". Kiểm chứng id trùng bằng Console: document.querySelectorAll("#datetime-iso-input").length → trả về 6. Heuristic: WCAG 1.3.1; WCAG 4.1.2. | F5: 3 - Lớn | G5: Cấp id duy nhất cho từng ô ngày giờ và gắn <label for> tương ứng; đặt aria-label riêng mô tả đúng vai trò từng mốc thời gian. | H5: A2_GUI-02-02_form-no-label.png, A2_GUI-02-02_duplicate-id-console.png | I5: Chưa gửi | J5: GUI-02-02
A6: =IF(D6="","","BUG-"&TEXT(ROW()-1,"000")) -> BUG-005 | B6: Khác | C6: Bug | D6: Có phần tử liên kết không có tên đọc được (link rỗng hoặc chỉ chứa icon). Xuất hiện trên cả màn hình A2 và trang chi tiết sự kiện A4. | E6: Chạy Lighthouse Accessibility trên /events/create và trang chi tiết sự kiện → mục "Links do not have a discernible name" → bung Failing Elements để xem phần tử cụ thể. Heuristic: WCAG 2.4.4; WCAG 4.1.2. | F6: 2 - Nhỏ | G6: Thêm text ẩn hoặc aria-label mô tả đích đến cho các liên kết chỉ có icon. | H6: A2_links-no-name.png, A4_links-no-name.png | I6: Chưa gửi | J6: GUI-03-09
A7: =IF(D7="","","BUG-"&TEXT(ROW()-1,"000")) -> BUG-006 | B7: A4 - Participants & Reviews | C7: Bug | D7: Thứ tự thẻ heading trên trang không đi liền mạch mà nhảy cấp (ví dụ h1 → h3). Người dùng trình đọc màn hình điều hướng theo cấu trúc heading sẽ hiểu sai phân cấp nội dung. Đây là màn hình duy nhất trong ba màn hình khảo sát bị lỗi này. | E7: Mở trang chi tiết sự kiện → Lighthouse → mục "Heading elements are not in a sequentially-descending order". Kiểm chứng bằng Console: $$("h1,h2,h3,h4,h5,h6").map(h=>h.tagName). Heuristic: WCAG 1.3.1. | F7: 2 - Nhỏ | G7: Sắp lại cấp heading cho liền mạch; không dùng thẻ heading để chỉnh cỡ chữ. | H7: A4_heading-order.png | I7: Chưa gửi | J7: GUI-01-11
A8: =IF(D8="","","BUG-"&TEXT(ROW()-1,"000")) -> BUG-007 | B8: A1 - Danh sách Events | C8: Usability | D8: Bảng danh sách sự kiện quá rộng nên các cột phía sau chỉ xem được bằng cách cuộn ngang, kể cả trên màn hình desktop lớn. Khi cuộn sang phải, cột tên sự kiện trượt mất khỏi khung nhìn nên người dùng không còn biết dòng đang xem thuộc sự kiện nào. | E8: Mở /dashboard/admin/events trên màn hình desktop → cuộn thanh ngang của bảng sang phải → quan sát cột SỰ KIỆN biến mất, chỉ còn mẩu chữ bị cắt ở mép trái. Heuristic: Nielsen #6 (Recognition rather than recall); WCAG 1.4.10. | F8: 3 - Lớn | G8: Ghim cố định cột tên sự kiện khi cuộn ngang; hoặc giảm số cột mặc định và cho phép người dùng tự chọn cột hiển thị. | H8: A1_GUI-01-10_horizontal-scroll-lost-column.png | I8: Chưa gửi | J8: GUI-01-10
A9: =IF(D9="","","BUG-"&TEXT(ROW()-1,"000")) -> BUG-008 | B9: A2 - Form Add/Edit Event | C9: Usability | D9: Một số trường bắt buộc không có dấu hiệu nhận biết nào trên giao diện. Người dùng chỉ phát hiện ra khi bấm Submit và bị từ chối — lỗi được phát hiện sau khi mắc phải thay vì được ngăn chặn từ đầu. | E9: Mở /dashboard/admin/events/create → rà toàn bộ trường, ghi nhận trường nào có dấu * và trường nào không → điền form bỏ trống các trường không đánh dấu → bấm Publish → quan sát trường nào bị báo lỗi dù trước đó không hề được đánh dấu bắt buộc. Heuristic: Nielsen #5 (Error prevention); Nielsen #4 (Consistency). | F9: 3 - Lớn | G9: Đánh dấu nhất quán mọi trường bắt buộc bằng một quy ước duy nhất và giải thích quy ước đó ở đầu form. | H9: A2_GUI-02-11_required-not-marked.png | I9: Chưa gửi | J9: GUI-02-11
A10: =IF(D10="","","BUG-"&TEXT(ROW()-1,"000")) -> BUG-009 | B10: Khác | C10: Bug | D10: Nhiều thao tác quan trọng hoàn tất mà không có bất kỳ phản hồi nào: xoá sự kiện (A1), lưu nháp (A2), và một số thao tác trên A4. Người dùng không biết thao tác đã thành công hay thất bại, dễ bấm lại lần nữa gây trùng lặp. | E10: A1: chọn một sự kiện → bấm nút xoá → xác nhận → quan sát không có toast/thông báo nào. A2: điền form → bấm Save as Draft → quan sát không có phản hồi. Heuristic: Nielsen #1 (Visibility of system status); Norman – Feedback; Shneiderman #3. | F10: 3 - Lớn | G10: Hiển thị toast xác nhận kết quả cho mọi thao tác ghi dữ liệu, nêu rõ thành công hay thất bại và tên đối tượng bị tác động. | H10: A1_GUI-04-02_delete-no-feedback.png, A2_GUI-04-02_savedraft-no-feedback.png | I10: Chưa gửi | J10: GUI-04-02
A11: =IF(D11="","","BUG-"&TEXT(ROW()-1,"000")) -> BUG-010 | B11: Khác | C11: Usability | D11: Hệ thống không cung cấp Undo hay Restore cho bất kỳ thao tác nào trên cả ba màn hình. Dialog xác nhận là cơ chế bảo vệ duy nhất — một khi đã xác nhận xoá, người dùng không có đường khôi phục. | E11: Thực hiện xoá một sự kiện hoặc huỷ một thao tác trên A1, A2, A4 → tìm nút Undo, Restore, thùng rác hoặc lịch sử khôi phục → không tìm thấy ở màn hình nào. Heuristic: Nielsen #3 (User control and freedom); Shneiderman #6 (Permit easy reversal of actions). | F11: 2 - Nhỏ | G11: Bổ sung Undo dạng toast trong khoảng 5–10 giây sau thao tác xoá, hoặc thùng rác lưu bản ghi đã xoá trong một khoảng thời gian. | H11: A1_GUI-04-08_no-undo.png | I11: Chưa gửi | J11: GUI-04-08
A12: =IF(D12="","","BUG-"&TEXT(ROW()-1,"000")) -> BUG-011 | B12: Khác | C12: Usability | D12: Sau khi hoàn tất một quy trình nhiều bước, hệ thống không tạo cảm giác kết thúc: không có bản tóm tắt kết quả, không nêu trạng thái mới, không gợi ý hành động tiếp theo. Người dùng phải tự kiểm tra lại để biết quy trình đã xong hay chưa. | E12: Hoàn tất tạo và phát hành một sự kiện trên A2 → quan sát sau khi bấm Publish có trang/dialog tổng kết nào không → không có. Lặp lại với thao tác trên A1 và A4. Heuristic: Shneiderman #4 (Design dialogs to yield closure); Nielsen #1. | F12: 2 - Nhỏ | G12: Sau khi hoàn tất quy trình, hiển thị màn hình hoặc dialog tổng kết nêu tên đối tượng, trạng thái mới và các hành động tiếp theo phù hợp. | H12: A2_GUI-04-09_no-closure.png | I12: Chưa gửi | J12: GUI-04-09
A13: =IF(D13="","","BUG-"&TEXT(ROW()-1,"000"))
A14: =IF(D14="","","BUG-"&TEXT(ROW()-1,"000"))
A15: =IF(D15="","","BUG-"&TEXT(ROW()-1,"000"))
A16: =IF(D16="","","BUG-"&TEXT(ROW()-1,"000"))
A17: =IF(D17="","","BUG-"&TEXT(ROW()-1,"000"))
A18: =IF(D18="","","BUG-"&TEXT(ROW()-1,"000"))
A19: =IF(D19="","","BUG-"&TEXT(ROW()-1,"000"))
A20: =IF(D20="","","BUG-"&TEXT(ROW()-1,"000"))
A21: =IF(D21="","","BUG-"&TEXT(ROW()-1,"000"))
A22: =IF(D22="","","BUG-"&TEXT(ROW()-1,"000"))
A23: =IF(D23="","","BUG-"&TEXT(ROW()-1,"000"))
A24: =IF(D24="","","BUG-"&TEXT(ROW()-1,"000"))
... A61: =IF(D61="","","BUG-"&TEXT(ROW()-1,"000"))
A63: Thang mức nghiêm trọng theo Nielsen (0–4). ID tự sinh khi bạn điền cột Mô tả.
A64: Mỗi dòng ở đây phải có một submission tương ứng trên Google Form — TA đối chiếu số lượng (§7).
